Failure # 1 (occurred at 2021-06-25_19-35-18)
Traceback (most recent call last):
  File "/home/hany606/.local/lib/python3.6/site-packages/ray/tune/trial_runner.py", line 718, in _process_trial
    results = self.trial_executor.fetch_result(trial)
  File "/home/hany606/.local/lib/python3.6/site-packages/ray/tune/ray_trial_executor.py", line 688, in fetch_result
    result = ray.get(trial_future[0], timeout=DEFAULT_GET_TIMEOUT)
  File "/home/hany606/.local/lib/python3.6/site-packages/ray/_private/client_mode_hook.py", line 62, in wrapper
    return func(*args, **kwargs)
  File "/home/hany606/.local/lib/python3.6/site-packages/ray/worker.py", line 1496, in get
    raise value
ray.exceptions.RayActorError: The actor died because of an error raised in its creation task, [36mray::PPO.__init__()[39m (pid=25133, ip=192.168.0.103)
  File "python/ray/_raylet.pyx", line 501, in ray._raylet.execute_task
  File "python/ray/_raylet.pyx", line 451, in ray._raylet.execute_task.function_executor
  File "/home/hany606/.local/lib/python3.6/site-packages/ray/_private/function_manager.py", line 563, in actor_method_executor
    return method(__ray_actor, *args, **kwargs)
  File "/home/hany606/.local/lib/python3.6/site-packages/ray/rllib/agents/trainer_template.py", line 123, in __init__
    Trainer.__init__(self, config, env, logger_creator)
  File "/home/hany606/.local/lib/python3.6/site-packages/ray/rllib/agents/trainer.py", line 548, in __init__
    super().__init__(config, logger_creator)
  File "/home/hany606/.local/lib/python3.6/site-packages/ray/tune/trainable.py", line 98, in __init__
    self.setup(copy.deepcopy(self.config))
  File "/home/hany606/.local/lib/python3.6/site-packages/ray/rllib/agents/trainer.py", line 709, in setup
    self._init(self.config, self.env_creator)
  File "/home/hany606/.local/lib/python3.6/site-packages/ray/rllib/agents/trainer_template.py", line 155, in _init
    num_workers=self.config["num_workers"])
  File "/home/hany606/.local/lib/python3.6/site-packages/ray/rllib/agents/trainer.py", line 797, in _make_workers
    logdir=self.logdir)
  File "/home/hany606/.local/lib/python3.6/site-packages/ray/rllib/evaluation/worker_set.py", line 100, in __init__
    spaces=spaces,
  File "/home/hany606/.local/lib/python3.6/site-packages/ray/rllib/evaluation/worker_set.py", line 407, in _make_worker
    spaces=spaces,
  File "/home/hany606/.local/lib/python3.6/site-packages/ray/rllib/evaluation/rollout_worker.py", line 563, in __init__
    policy_config["framework"]))
RuntimeError: GPUs were assigned to this worker by Ray, but your DL framework (tf) reports GPU acceleration is disabled. This could be due to a bad CUDA- or tf installation.

