Failure # 1 (occurred at 2021-06-25_18-49-23)
Traceback (most recent call last):
  File "/home/hany606/.local/lib/python3.6/site-packages/ray/tune/trial_runner.py", line 718, in _process_trial
    results = self.trial_executor.fetch_result(trial)
  File "/home/hany606/.local/lib/python3.6/site-packages/ray/tune/ray_trial_executor.py", line 688, in fetch_result
    result = ray.get(trial_future[0], timeout=DEFAULT_GET_TIMEOUT)
  File "/home/hany606/.local/lib/python3.6/site-packages/ray/_private/client_mode_hook.py", line 62, in wrapper
    return func(*args, **kwargs)
  File "/home/hany606/.local/lib/python3.6/site-packages/ray/worker.py", line 1494, in get
    raise value.as_instanceof_cause()
ray.exceptions.RayTaskError(ValueError): [36mray::PPO.train_buffered()[39m (pid=14222, ip=192.168.0.103)
  File "python/ray/_raylet.pyx", line 501, in ray._raylet.execute_task
  File "python/ray/_raylet.pyx", line 451, in ray._raylet.execute_task.function_executor
  File "/home/hany606/.local/lib/python3.6/site-packages/ray/_private/function_manager.py", line 563, in actor_method_executor
    return method(__ray_actor, *args, **kwargs)
  File "/home/hany606/.local/lib/python3.6/site-packages/ray/tune/trainable.py", line 173, in train_buffered
    result = self.train()
  File "/home/hany606/.local/lib/python3.6/site-packages/ray/rllib/agents/trainer.py", line 605, in train
    raise e
  File "/home/hany606/.local/lib/python3.6/site-packages/ray/rllib/agents/trainer.py", line 594, in train
    result = Trainable.train(self)
  File "/home/hany606/.local/lib/python3.6/site-packages/ray/tune/trainable.py", line 232, in train
    result = self.step()
  File "/home/hany606/.local/lib/python3.6/site-packages/ray/rllib/agents/trainer_template.py", line 173, in step
    res = next(self.train_exec_impl)
  File "/home/hany606/.local/lib/python3.6/site-packages/ray/util/iter.py", line 756, in __next__
    return next(self.built_iterator)
  File "/home/hany606/.local/lib/python3.6/site-packages/ray/util/iter.py", line 783, in apply_foreach
    for item in it:
  File "/home/hany606/.local/lib/python3.6/site-packages/ray/util/iter.py", line 783, in apply_foreach
    for item in it:
  File "/home/hany606/.local/lib/python3.6/site-packages/ray/util/iter.py", line 843, in apply_filter
    for item in it:
  File "/home/hany606/.local/lib/python3.6/site-packages/ray/util/iter.py", line 843, in apply_filter
    for item in it:
  File "/home/hany606/.local/lib/python3.6/site-packages/ray/util/iter.py", line 783, in apply_foreach
    for item in it:
  File "/home/hany606/.local/lib/python3.6/site-packages/ray/util/iter.py", line 783, in apply_foreach
    for item in it:
  File "/home/hany606/.local/lib/python3.6/site-packages/ray/util/iter.py", line 783, in apply_foreach
    for item in it:
  [Previous line repeated 1 more time]
  File "/home/hany606/.local/lib/python3.6/site-packages/ray/util/iter.py", line 876, in apply_flatten
    for item in it:
  File "/home/hany606/.local/lib/python3.6/site-packages/ray/util/iter.py", line 828, in add_wait_hooks
    item = next(it)
  File "/home/hany606/.local/lib/python3.6/site-packages/ray/util/iter.py", line 783, in apply_foreach
    for item in it:
  File "/home/hany606/.local/lib/python3.6/site-packages/ray/util/iter.py", line 783, in apply_foreach
    for item in it:
  File "/home/hany606/.local/lib/python3.6/site-packages/ray/util/iter.py", line 783, in apply_foreach
    for item in it:
  [Previous line repeated 1 more time]
  File "/home/hany606/.local/lib/python3.6/site-packages/ray/util/iter.py", line 471, in base_iterator
    yield ray.get(futures, timeout=timeout)
  File "/home/hany606/.local/lib/python3.6/site-packages/ray/_private/client_mode_hook.py", line 62, in wrapper
    return func(*args, **kwargs)
ray.exceptions.RayTaskError(ValueError): [36mray::RolloutWorker.par_iter_next()[39m (pid=14223, ip=192.168.0.103)
  File "python/ray/_raylet.pyx", line 501, in ray._raylet.execute_task
  File "python/ray/_raylet.pyx", line 451, in ray._raylet.execute_task.function_executor
  File "/home/hany606/.local/lib/python3.6/site-packages/ray/_private/function_manager.py", line 563, in actor_method_executor
    return method(__ray_actor, *args, **kwargs)
  File "/home/hany606/.local/lib/python3.6/site-packages/ray/util/iter.py", line 1151, in par_iter_next
    return next(self.local_it)
  File "/home/hany606/.local/lib/python3.6/site-packages/ray/rllib/evaluation/rollout_worker.py", line 333, in gen_rollouts
    yield self.sample()
  File "/home/hany606/.local/lib/python3.6/site-packages/ray/rllib/evaluation/rollout_worker.py", line 726, in sample
    batches = [self.input_reader.next()]
  File "/home/hany606/.local/lib/python3.6/site-packages/ray/rllib/evaluation/sampler.py", line 99, in next
    batches = [self.get_data()]
  File "/home/hany606/.local/lib/python3.6/site-packages/ray/rllib/evaluation/sampler.py", line 226, in get_data
    item = next(self.rollout_provider)
  File "/home/hany606/.local/lib/python3.6/site-packages/ray/rllib/evaluation/sampler.py", line 616, in _env_runner
    sample_collector=sample_collector,
  File "/home/hany606/.local/lib/python3.6/site-packages/ray/rllib/evaluation/sampler.py", line 811, in _process_observations
    policy_id).transform(raw_obs)
  File "/home/hany606/.local/lib/python3.6/site-packages/ray/rllib/models/preprocessors.py", line 257, in transform
    self.check_shape(observation)
  File "/home/hany606/.local/lib/python3.6/site-packages/ray/rllib/models/preprocessors.py", line 68, in check_shape
    observation, self._obs_space)
ValueError: ('Observation ({}) outside given space ({})!', array([1000., 1500.]), Dict(opponent_action:Box(-1.0, 1.0, (2,), float32), opponent_obs:Box(0.0, 3000.0, (2,), float32), own_obs:Box(0.0, 3000.0, (2,), float32)))

