Failure # 1 (occurred at 2021-06-26_16-17-24)
Traceback (most recent call last):
  File "/home/hany606/.local/lib/python3.6/site-packages/ray/tune/trial_runner.py", line 718, in _process_trial
    results = self.trial_executor.fetch_result(trial)
  File "/home/hany606/.local/lib/python3.6/site-packages/ray/tune/ray_trial_executor.py", line 688, in fetch_result
    result = ray.get(trial_future[0], timeout=DEFAULT_GET_TIMEOUT)
  File "/home/hany606/.local/lib/python3.6/site-packages/ray/_private/client_mode_hook.py", line 62, in wrapper
    return func(*args, **kwargs)
  File "/home/hany606/.local/lib/python3.6/site-packages/ray/worker.py", line 1494, in get
    raise value.as_instanceof_cause()
ray.exceptions.RayTaskError(AttributeError): [36mray::PPO.train_buffered()[39m (pid=14800, ip=10.91.73.206)
  File "python/ray/_raylet.pyx", line 501, in ray._raylet.execute_task
  File "python/ray/_raylet.pyx", line 451, in ray._raylet.execute_task.function_executor
  File "/home/hany606/.local/lib/python3.6/site-packages/ray/_private/function_manager.py", line 563, in actor_method_executor
    return method(__ray_actor, *args, **kwargs)
  File "/home/hany606/.local/lib/python3.6/site-packages/ray/tune/trainable.py", line 173, in train_buffered
    result = self.train()
  File "/home/hany606/.local/lib/python3.6/site-packages/ray/rllib/agents/trainer.py", line 608, in train
    raise e
  File "/home/hany606/.local/lib/python3.6/site-packages/ray/rllib/agents/trainer.py", line 594, in train
    result = Trainable.train(self)
  File "/home/hany606/.local/lib/python3.6/site-packages/ray/tune/trainable.py", line 294, in train
    self.log_result(result)
  File "/home/hany606/.local/lib/python3.6/site-packages/ray/rllib/agents/trainer.py", line 630, in log_result
    self.callbacks.on_train_result(trainer=self, result=result)
  File "train_1v1_simple2.py", line 136, in on_train_result
    print(pretty_print(result["episode_len_mean"]))
  File "/home/hany606/.local/lib/python3.6/site-packages/ray/tune/logger.py", line 724, in pretty_print
    result.update(config=None)  # drop config from pretty print
AttributeError: 'numpy.float64' object has no attribute 'update'

