Failure # 1 (occurred at 2021-07-18_00-07-14)
Traceback (most recent call last):
  File "/home/hany606/.local/lib/python3.6/site-packages/ray/tune/trial_runner.py", line 718, in _process_trial
    results = self.trial_executor.fetch_result(trial)
  File "/home/hany606/.local/lib/python3.6/site-packages/ray/tune/ray_trial_executor.py", line 688, in fetch_result
    result = ray.get(trial_future[0], timeout=DEFAULT_GET_TIMEOUT)
  File "/home/hany606/.local/lib/python3.6/site-packages/ray/_private/client_mode_hook.py", line 62, in wrapper
    return func(*args, **kwargs)
  File "/home/hany606/.local/lib/python3.6/site-packages/ray/worker.py", line 1494, in get
    raise value.as_instanceof_cause()
ray.exceptions.RayTaskError(TuneError): [36mray::ImplicitFunc.train_buffered()[39m (pid=3340, ip=10.91.54.72)
  File "python/ray/_raylet.pyx", line 501, in ray._raylet.execute_task
  File "python/ray/_raylet.pyx", line 451, in ray._raylet.execute_task.function_executor
  File "/home/hany606/.local/lib/python3.6/site-packages/ray/_private/function_manager.py", line 563, in actor_method_executor
    return method(__ray_actor, *args, **kwargs)
  File "/home/hany606/.local/lib/python3.6/site-packages/ray/tune/trainable.py", line 173, in train_buffered
    result = self.train()
  File "/home/hany606/.local/lib/python3.6/site-packages/ray/tune/trainable.py", line 232, in train
    result = self.step()
  File "/home/hany606/.local/lib/python3.6/site-packages/ray/tune/function_runner.py", line 366, in step
    self._report_thread_runner_error(block=True)
  File "/home/hany606/.local/lib/python3.6/site-packages/ray/tune/function_runner.py", line 513, in _report_thread_runner_error
    ("Trial raised an exception. Traceback:\n{}".format(err_tb_str)
ray.tune.error.TuneError: Trial raised an exception. Traceback:
[36mray::ImplicitFunc.train_buffered()[39m (pid=3340, ip=10.91.54.72)
  File "/home/hany606/.local/lib/python3.6/site-packages/ray/tune/function_runner.py", line 248, in run
    self._entrypoint()
  File "/home/hany606/.local/lib/python3.6/site-packages/ray/tune/function_runner.py", line 316, in entrypoint
    self._status_reporter.get_checkpoint())
  File "/home/hany606/.local/lib/python3.6/site-packages/ray/tune/function_runner.py", line 580, in _trainable_func
    output = fn()
  File "train_selfplay.py", line 93, in selfplay_train_func
    pred_agent = PPOTrainer(env="Pred", config=config)   # https://github.com/ray-project/ray/blob/master/rllib/agents/trainer.py
  File "/home/hany606/.local/lib/python3.6/site-packages/ray/rllib/agents/trainer_template.py", line 123, in __init__
    Trainer.__init__(self, config, env, logger_creator)
  File "/home/hany606/.local/lib/python3.6/site-packages/ray/rllib/agents/trainer.py", line 548, in __init__
    super().__init__(config, logger_creator)
  File "/home/hany606/.local/lib/python3.6/site-packages/ray/tune/trainable.py", line 98, in __init__
    self.setup(copy.deepcopy(self.config))
  File "/home/hany606/.local/lib/python3.6/site-packages/ray/rllib/agents/trainer.py", line 709, in setup
    self._init(self.config, self.env_creator)
  File "/home/hany606/.local/lib/python3.6/site-packages/ray/rllib/agents/trainer_template.py", line 155, in _init
    num_workers=self.config["num_workers"])
  File "/home/hany606/.local/lib/python3.6/site-packages/ray/rllib/agents/trainer.py", line 797, in _make_workers
    logdir=self.logdir)
  File "/home/hany606/.local/lib/python3.6/site-packages/ray/rllib/evaluation/worker_set.py", line 100, in __init__
    spaces=spaces,
  File "/home/hany606/.local/lib/python3.6/site-packages/ray/rllib/evaluation/worker_set.py", line 407, in _make_worker
    spaces=spaces,
  File "/home/hany606/.local/lib/python3.6/site-packages/ray/rllib/evaluation/rollout_worker.py", line 563, in __init__
    policy_config["framework"]))
RuntimeError: GPUs were assigned to this worker by Ray, but your DL framework (tf) reports GPU acceleration is disabled. This could be due to a bad CUDA- or tf installation.

